Workbook

Sheet Project Summary
A1: Commercial Carpet Project Summary
A3: Field | B3: Response | C3: Notes
A4: Project ID | B4: CW-0000 | C4: Must match the project folder
A5: Customer / site
A6: Site address
A7: Contact person
A8: Installer / company
A9: Installer contact
A10: Date surveyed
A11: Date installed
A12: Floor-plan PDF
A13: Plan revision / version
A14: Annotator
A15: Units used | B15: metres
A16: PDF page count
A17: Pages installed
A18: Scale verified? | B18: No | C18: Do not guess scale
A19: Pixels per metre
A20: Scale reference used
A21: Subfloor condition
A22: Site access notes
A23: General notes

Sheet Rooms
A1: Room Register - one row per room
A3: Room ID | B3: Page | C3: Room label / number | D3: Material | E3: Length (m) | F3: Width (m) | G3: Area (m2) | H3: Carpet required (LM) | I3: Notes
G4: =IF(OR(E4="",F4=""),"",E4*F4) | H4: =IF(G4="","",G4/IFERROR('Product & Rolls'!B10,1))
G5: =IF(OR(E5="",F5=""),"",E5*F5) | H5: =IF(G5="","",G5/IFERROR('Product & Rolls'!B10,1))
G6: =IF(OR(E6="",F6=""),"",E6*F6) | H6: =IF(G6="","",G6/IFERROR('Product & Rolls'!B10,1))
G7: =IF(OR(E7="",F7=""),"",E7*F7) | H7: =IF(G7="","",G7/IFERROR('Product & Rolls'!B10,1))
G8: =IF(OR(E8="",F8=""),"",E8*F8) | H8: =IF(G8="","",G8/IFERROR('Product & Rolls'!B10,1))
G9: =IF(OR(E9="",F9=""),"",E9*F9) | H9: =IF(G9="","",G9/IFERROR('Product & Rolls'!B10,1))
G10: =IF(OR(E10="",F10=""),"",E10*F10) | H10: =IF(G10="","",G10/IFERROR('Product & Rolls'!B10,1))
G11: =IF(OR(E11="",F11=""),"",E11*F11) | H11: =IF(G11="","",G11/IFERROR('Product & Rolls'!B10,1))
G12: =IF(OR(E12="",F12=""),"",E12*F12) | H12: =IF(G12="","",G12/IFERROR('Product & Rolls'!B10,1))
G13: =IF(OR(E13="",F13=""),"",E13*F13) | H13: =IF(G13="","",G13/IFERROR('Product & Rolls'!B10,1))
G14: =IF(OR(E14="",F14=""),"",E14*F14) | H14: =IF(G14="","",G14/IFERROR('Product & Rolls'!B10,1))
G15: =IF(OR(E15="",F15=""),"",E15*F15) | H15: =IF(G15="","",G15/IFERROR('Product & Rolls'!B10,1))
G16: =IF(OR(E16="",F16=""),"",E16*F16) | H16: =IF(G16="","",G16/IFERROR('Product & Rolls'!B10,1))
G17: =IF(OR(E17="",F17=""),"",E17*F17) | H17: =IF(G17="","",G17/IFERROR('Product & Rolls'!B10,1))
G18: =IF(OR(E18="",F18=""),"",E18*F18) | H18: =IF(G18="","",G18/IFERROR('Product & Rolls'!B10,1))
G19: =IF(OR(E19="",F19=""),"",E19*F19) | H19: =IF(G19="","",G19/IFERROR('Product & Rolls'!B10,1))
G20: =IF(OR(E20="",F20=""),"",E20*F20) | H20: =IF(G20="","",G20/IFERROR('Product & Rolls'!B10,1))
G21: =IF(OR(E21="",F21=""),"",E21*F21) | H21: =IF(G21="","",G21/IFERROR('Product & Rolls'!B10,1))
G22: =IF(OR(E22="",F22=""),"",E22*F22) | H22: =IF(G22="","",G22/IFERROR('Product & Rolls'!B10,1))
G23: =IF(OR(E23="",F23=""),"",E23*F23) | H23: =IF(G23="","",G23/IFERROR('Product & Rolls'!B10,1))
G24: =IF(OR(E24="",F24=""),"",E24*F24) | H24: =IF(G24="","",G24/IFERROR('Product & Rolls'!B10,1))
G25: =IF(OR(E25="",F25=""),"",E25*F25) | H25: =IF(G25="","",G25/IFERROR('Product & Rolls'!B10,1))
G26: =IF(OR(E26="",F26=""),"",E26*F26) | H26: =IF(G26="","",G26/IFERROR('Product & Rolls'!B10,1))
G27: =IF(OR(E27="",F27=""),"",E27*F27) | H27: =IF(G27="","",G27/IFERROR('Product & Rolls'!B10,1))
G28: =IF(OR(E28="",F28=""),"",E28*F28) | H28: =IF(G28="","",G28/IFERROR('Product & Rolls'!B10,1))
G29: =IF(OR(E29="",F29=""),"",E29*F29) | H29: =IF(G29="","",G29/IFERROR('Product & Rolls'!B10,1))
G30: =IF(OR(E30="",F30=""),"",E30*F30) | H30: =IF(G30="","",G30/IFERROR('Product & Rolls'!B10,1))
G31: =IF(OR(E31="",F31=""),"",E31*F31) | H31: =IF(G31="","",G31/IFERROR('Product & Rolls'!B10,1))
G32: =IF(OR(E32="",F32=""),"",E32*F32) | H32: =IF(G32="","",G32/IFERROR('Product & Rolls'!B10,1))
G33: =IF(OR(E33="",F33=""),"",E33*F33) | H33: =IF(G33="","",G33/IFERROR('Product & Rolls'!B10,1))
G34: =IF(OR(E34="",F34=""),"",E34*F34) | H34: =IF(G34="","",G34/IFERROR('Product & Rolls'!B10,1))
G35: =IF(OR(E35="",F35=""),"",E35*F35) | H35: =IF(G35="","",G35/IFERROR('Product & Rolls'!B10,1))
G36: =IF(OR(E36="",F36=""),"",E36*F36) | H36: =IF(G36="","",G36/IFERROR('Product & Rolls'!B10,1))
G37: =IF(OR(E37="",F37=""),"",E37*F37) | H37: =IF(G37="","",G37/IFERROR('Product & Rolls'!B10,1))
G38: =IF(OR(E38="",F38=""),"",E38*F38) | H38: =IF(G38="","",G38/IFERROR('Product & Rolls'!B10,1))
G39: =IF(OR(E39="",F39=""),"",E39*F39) | H39: =IF(G39="","",G39/IFERROR('Product & Rolls'!B10,1))
G40: =IF(OR(E40="",F40=""),"",E40*F40) | H40: =IF(G40="","",G40/IFERROR('Product & Rolls'!B10,1))
G41: =IF(OR(E41="",F41=""),"",E41*F41) | H41: =IF(G41="","",G41/IFERROR('Product & Rolls'!B10,1))
...

Sheet Product & Rolls
A1: Product and Roll Allocation
A3: Field | B3: Response | C3: Notes
A4: Product / colour
A5: Manufacturer
A6: Batch / dye lot
A7: Carpet width (m)
A8: Roll width (m) | B8: 3.66 | C8: Standard carpet roll width
A9: Pattern repeat
A10: Pattern match required?
A11: Pile direction required?
A12: Direction notes

Sheet Rolls
A1: Roll Allocation - one row per roll
A3: Roll ID | B3: Source roll / batch | C3: Length available (LM) | D3: Length allocated (LM) | E3: Rooms served | F3: Remaining offcut (LM)
F4: =IF(C4="","",C4-IFERROR(D4,0))
F5: =IF(C5="","",C5-IFERROR(D5,0))
F6: =IF(C6="","",C6-IFERROR(D6,0))
F7: =IF(C7="","",C7-IFERROR(D7,0))
F8: =IF(C8="","",C8-IFERROR(D8,0))
F9: =IF(C9="","",C9-IFERROR(D9,0))
F10: =IF(C10="","",C10-IFERROR(D10,0))
F11: =IF(C11="","",C11-IFERROR(D11,0))
F12: =IF(C12="","",C12-IFERROR(D12,0))
F13: =IF(C13="","",C13-IFERROR(D13,0))
F14: =IF(C14="","",C14-IFERROR(D14,0))
F15: =IF(C15="","",C15-IFERROR(D15,0))
... F33: =IF(C33="","",C33-IFERROR(D33,0))

Sheet Joins
A1: Join Schedule - one row per join
A3: Join ID | B3: Room ID | C3: Page | D3: Join location / description | E3: Planned position | F3: Actual position | G3: Reason moved | H3: Visible / accepted? | I3: Attachment

Sheet Offcuts
A1: Offcut Reuse - one row per offcut
A3: Offcut ID | B3: Source roll | C3: Size / length | D3: Usable? | E3: Reused for room / area | F3: Reuse decision | G3: Reason not reused

Sheet Outcome & Feedback
A1: Quantity Outcome and Installer Feedback
A3: Field | B3: Response | C3: Notes
A4: Total measured carpet area (m2)
A5: Total carpet ordered (LM)
A6: Total carpet installed (LM)
A7: Waste / offcut produced (LM)
A8: Waste percentage | B8: =IFERROR((B5-B6)/B5*100,"") | C8: Calculated from ordered and installed LM
A9: Reusable offcut total (LM)
A10: Material shortage?
A11: Extra material ordered (LM)
A12: Final quantity notes
A13: Were room dimensions usable?
A14: Were planned joins practical?
A15: Difficult areas
A16: Waste causes
A17: Missed site conditions
A18: What should the AI learn?
A19: Installer confidence (1-5)
A20: Installer sign-off name
A21: Sign-off date

Sheet Completion Checklist
A1: Dataset Completion Checklist
A3: Task | B3: Complete? | C3: Date / reviewer | D3: Notes
A4: Original floor-plan PDF stored
A5: All pages rendered
A6: Room polygons completed
A7: Dimension text recorded
A8: Doors/windows/walls/stairs annotated
A9: Dunlop table rows recorded if applicable
A10: Installer worksheet completed
A11: Final layout attached
A12: Join schedule completed
A13: Offcut decisions completed
A14: Metadata JSON updated
A15: Official annotations validated
... A18: Project status set to verified
